Workbook

Sheet Master Budget 20252026
A1: Master Budget - Telfer BIPOC Business Society
A2: 2024/2025
A4: Master Budget
H5: April 2024 - July 2024 | K5: August 2024 - November 2024 | N5: December 2024 - March 2025
A6: Revenue | H6: Expected | I6: Actuals | J6: Variance | K6: Expected | L6: Actuals | M6: Variance | N6: Expected | O6: Actuals | P6: Variance
A7: Membership Revenue
B8: Membership Sales
B9: Other
A10: Total Membership Revenue | H10: =sum(H8:H9) -> 0 | I10: =sum(I8:I9) -> 0 | K10: =sum(K8:K9) -> 0 | L10: =sum(L8:L9) -> 0 | N10: 0 | O10: 0
A11: Event Revenue
B12: Estimated Revenue from Networking Event – CGI
B13: Estimated Revenue from Office Tour #1 | H13: ='Behind the Scenes - Apr 2024'!H10 -> #REF! | I13: ='Behind the Scenes - Apr 2024'!I10 -> #REF! | K13: 0 | L13: 0 | N13: ='Behind the Scenes - Apr 2024'!N10 -> #REF! | O13: ='Behind the Scenes - Apr 2024'!O10 -> #REF!
B14: Estimated Revenue from Office Tour #2 | K14: ='BBQ Event - Sept 2024'!H9 -> #REF! | L14: ='BBQ Event - Sept 2024'!I9 -> #REF!
B15: Estimated Revenue from Case Competition – CGI | K15: ='Networking Event (CGI) - Sept '!H10 -> 0 | L15: ='Networking Event (CGI) - Sept '!I10 -> 0
B16: Estimated Revenue from WBC Panel Event | N16: ='PWL Financial Lit - Mar 2025'!H10 -> #REF! | O16: ='PWL Financial Lit - Mar 2025'!I10 -> #REF!
B17: Estimated Revenue from Financial Literacy Event | N17: 0 | O17: 0
B18: Estimated Revenue from Networking Event – CGI | N18: ='BBS x Afriqcan Case Comp - Feb 2025'!H10 -> #REF! | O18: ='BBS x Afriqcan Case Comp - Feb 2025'!I10 -> #REF!
B19: Estimated Revenue from Toronto Trip
A21: Total Event Revenue | H21: =sum(H13:H20) -> #REF! | I21: =sum(I13:I20) -> #REF! | K21: =sum(K13:K20) -> #REF! | L21: =sum(L13:L20) -> #REF! | N21: =sum(N13:N20) -> #REF! | O21: =sum(O13:O20) -> #REF!
A22: Sponsorship Revenue
B23: Deloitte
B24: Ottawa Tourism
B25: Poulet Rouge
B26: UOSU Funding (fall)
B27: UOSU Funding (winter)
B28: CPP
A29: Total Sponsorship Revenue | H29: =sum(H23:H28) -> 0 | I29: =sum(I23:I28) -> 0 | K29: =sum(K23:K28) -> 0 | L29: =sum(L23:L28) -> 0 | M29: =K29-L29 -> 0 | N29: =sum(N23:N28) -> 0 | O29: =sum(O23:O28) -> 0 | P29: =N29-O29 -> 0
A31: Total Revenue | H31: =sum(H10,H21,H29) -> #REF! | I31: =sum(I10,I21,I29) -> #REF! | K31: =sum(K10,K21,K29) -> #REF! | L31: =sum(L10,L21,L29) -> #REF! | M31: =K31-L31 -> #REF! | N31: =sum(N10,N21,N29) -> #REF! | O31: =sum(O10,O21,O29) -> #REF! | P31: =N31-O31 -> #REF!
A33: Expenses | H33: Expected | I33: Actuals | J33: Variance | K33: Expected | L33: Actuals | M33: Variance | N33: Expected | O33: Actuals | P33: Variance
A34: Event Expenses
B35: Networking Event – CGI Expenditures | N35: ='Behind the Scenes - Apr 2024'!N49 -> #REF! | O35: ='Behind the Scenes - Apr 2024'!O49 -> #REF!
B36: Office Tour #1 Expenditures
B37: Office Tour #2 Expenditures
B38: Case Competition – CGI Expenditures
B39: WBC Panel Event Expenditures
B40: Financial Literacy Event Expenditures
B41: Networking Event – CGI Expenditures
B42: Toronto Trip Expenditures
A43: Total Social Expenses
A44: Other
...

Sheet Networking Event (CGI)  - Sept 
A1: Networking Event (CGI) - Telfer BIPOC Business Society
A2: 45901
A4: Networking Event (CGI) - September 2025
A5: Revenue | F5: Price | G5: Units | H5: Expected | I5: Actuals | J5: Variance
A6: Ticket Sales
B7: Member Ticket Sales | H7: 0 | I7: 0
B8: Non-Member Ticket Sales | H8: 0 | I8: 0
B9: Other | H9: 0 | I9: 0
A10: Total Event Revenue | H10: =sum(H7:H9) -> 0 | I10: =sum(I7:I9) -> 0
A12: Expenses | F12: Price | G12: Units | H12: Expected | I12: Actuals | J12: Variance
A13: Event Management
B14: Food & Beverages | H14: 500
B15: Venue | H15: 200
B16: Miscellaneous | H16: 300
A17: Total Event Management Expenses | H17: =sum(H14:H16) -> 1000 | I17: =SUM(I14:I16) -> 0 | J17: =I17-H17 -> -1000
A19: Total Event Expenses | H19: =H17 -> 1000 | I19: =I17/2 -> 0 | J19: =I19-H19 -> -1000
A21: Net Income (Loss) | H21: =H10-H19 -> -1000 | I21: =I10-I19 -> 0 | J21: =I21-H21 -> 1000

Sheet  Office Tour #1 - Sept 2025
A1: Office Tour #1 - Telfer BIPOC Business Society
A2: 45901
A4: Office Tour #1 - September 2025
A5: Revenue | F5: Price | G5: Units | H5: Expected | I5: Actuals | J5: Variance
A6: Ticket Sales
B7: Member Ticket Sales
B8: Non-Member Ticket Sales
B9: Other
A10: Total Event Revenue | H10: =sum(H7:H9) -> 0 | I10: =sum(I7:I9) -> 0
A12: Expenses | F12: Price | G12: Units | H12: Expected | I12: Actuals | J12: Variance
A13: Event Management
B14: Transportation/Refreshments/Admin | H14: 1000
A16: Total Event Management Expenses | H16: =sum(H14:H15) -> 1000 | I16: =sum(I14:I15) -> 0 | J16: =I16-H16 -> -1000
A18: Total Event Expenses | H18: =H16 -> 1000 | I18: =I16/2 -> 0 | J18: =I18-H18 -> -1000
A20: Net Income (Loss) | H20: =H10-H18 -> -1000 | I20: =I10-I18 -> 0 | J20: =I20-H20 -> 1000

Sheet Office Tour #2 - Oct 2025
A1: Office Tour #2 - Telfer BIPOC Business Society
A2: 45931
A4: Office Tour #2 - October 2025
A5: Revenue | F5: Price | G5: Units | H5: Expected | I5: Actuals | J5: Variance
A6: Ticket Sales
B7: Member Ticket Sales
B8: Non-Member Ticket Sales
B9: Other
A10: Total Event Revenue | H10: =sum(H7:H9) -> 0 | I10: =sum(I7:I9) -> 0
A12: Expenses | F12: Price | G12: Units | H12: Expected | I12: Actuals | J12: Variance
A13: Event Management
B14: Transportation/Refreshments/Admin | H14: 1000
A16: Total Event Management Expenses | H16: =sum(H14:H15) -> 1000 | I16: =sum(I14:I15) -> 0 | J16: =I16-H16 -> -1000
A18: Total Event Expenses | H18: =H16 -> 1000 | I18: =I16/2 -> 0 | J18: =I18-H18 -> -1000
A20: Net Income (Loss) | H20: =H10-H18 -> -1000 | I20: =I10-I18 -> 0 | J20: =I20-H20 -> 1000

Sheet Case Competition (CGI) - Oct 20
A1: Case Competition (CGI) - Telfer BIPOC Business Society
A2: 45931
A4: Case Competition (CGI) - October 2025
A5: Revenue | F5: Price | G5: Units | H5: Expected | I5: Actuals | J5: Variance
A6: Ticket Sales
B7: Member Ticket Sales | H7: 0 | I7: 0
B8: Non-Member Ticket Sales | H8: 0 | I8: 0
B9: Other | H9: 0 | I9: 0
A10: Total Event Revenue | H10: =sum(H7:H9) -> 0 | I10: =sum(I7:I9) -> 0
A12: Expenses | F12: Price | G12: Units | H12: Expected | I12: Actuals | J12: Variance
A13: Event Management
B14: Food & Beverages | H14: 500
B15: Venue | H15: 200
B16: Prizess | H16: 300
A17: Total Event Management Expenses | H17: =sum(H14:H16) -> 1000 | I17: =SUM(I14:I16) -> 0 | J17: =I17-H17 -> -1000
A19: Total Event Expenses | H19: =H17 -> 1000 | I19: =I17/2 -> 0 | J19: =I19-H19 -> -1000
A21: Net Income (Loss) | H21: =H10-H19 -> -1000 | I21: =I10-I19 -> 0 | J21: =I21-H21 -> 1000

Sheet WBC Panel Event - Nov 2025
A1: WBC Panel Event - Telfer BIPOC Business Society
A2: 45962
A4: WBC Panel Event - November 2025
A5: Revenue | F5: Price | G5: Units | H5: Expected | I5: Actuals | J5: Variance
A6: Ticket Sales
B7: Member Ticket Sales | H7: 0 | I7: 0
B8: Non-Member Ticket Sales | H8: 0 | I8: 0
B9: Other | H9: 0 | I9: 0
A10: Total Event Revenue | H10: =sum(H7:H9) -> 0 | I10: =sum(I7:I9) -> 0
A12: Expenses | F12: Price | G12: Units | H12: Expected | I12: Actuals | J12: Variance
A13: Event Management
B14: Food & Beverages | H14: 500
B15: Venue | H15: 200
B16: Prizess | H16: 300
A17: Total Event Management Expenses | H17: =sum(H14:H16) -> 1000 | I17: =SUM(I14:I16) -> 0 | J17: =I17-H17 -> -1000
A19: Total Event Expenses | H19: =H17 -> 1000 | I19: =I17/2 -> 0 | J19: =I19-H19 -> -1000
A21: Net Income (Loss) | H21: =H10-H19 -> -1000 | I21: =I10-I19 -> 0 | J21: =I21-H21 -> 1000

Sheet Toronto Trip - Mar 2025
A1: Toronto Trip - Telfer BIPOC Business Society
A2: 45717
A4: Toronto Trip - March 2025
A5: Revenue | F5: Price | G5: Units | H5: Expected | I5: Actuals | J5: Variance
A6: Ticket Sales | L6: 150 | M6: 175
A7: Member | F7: 150 | G7: 7 | H7: 1500 | I7: =F7*G7 -> 1050 | K7: - | L7: Miguel | M7: Lea | N7: -
A8: earlybird | F8: 175 | G8: 14 | H8: 3700 | I8: =F8*G8 -> 2450 | K8: - | L8: Funmi | M8: Naya | N8: -
A9: Full price | F9: 195 | H9: 0 | I9: =G9*F9 -> 0 | K9: - | L9: Shaan | M9: Ahmed | N9: -
A10: Sponsorship | F10: 750 | G10: 3 | H10: 2250 | I10: =G10*F10 -> 2250 | K10: - | L10: Simran | M10: Zaina | N10: -
H11: 0 | K11: - | L11: Kai | M11: Sacha | N11: -
A12: Total Event Revenue | H12: 7450 | I12: =sum(I7:I10) -> 5750 | J12: =H12-I12 -> 1700 | K12: - | L12: Alysse | M12: Karsten | N12: -
K13: - | L13: Farah | M13: Bilal | N13: -
A14: Expenses | F14: Price | G14: Units | H14: Expected | I14: Actuals | J14: Variance | K14: - | L14: Tolu | M14: Amin | N14: -
A15: Accomodation | L15: Irene | M15: Aaron | N15: -
B16: Hotel (quad rooming) | F16: 230.45 | G16: 8 | H16: 1843.68 | I16: =G16*F16 -> 1843.6 | K16: - | L16: Niusha | M16: Kareem | N16: -
B17: Food & Beverages | F17: 20.5 | G17: 0 | H17: 1200 | I17: =55.33+10.45 -> 65.78 | M17: Jenah | N17: -
B18: External Representative Gifts | H18: 300 | I18: =142.04+2.83+38.14 -> 183.01 | M18: Jasmeen | N18: -
A19: Total Accomodation Expenses | H19: 3043.68 | I19: =sum(I16:I18) -> 2092.39 | M19: Mikael | N19: -
A20: Transportation - Via Rail | M20: Michael | N20: -
A21: Going | F21: 60.5 | G21: 24 | H21: 1769 | I21: =F21*G21 -> 1452
A22: Return | F22: 66.55 | G22: 24 | H22: 1943 | I22: =F22*G22 -> 1597.2
B24: Train | H24: 3712 | I24: 3049.2
A25: Total Transportation Expenses | H25: 4194.56 | I25: =I24*1.13 -> 3445.596 | L25: =4575-I19+750+750-100 -> 3882.61
L26: 850
A27: Total Event Expenses | H27: 7382.88 | I27: =I19+I25 -> 5537.986 | L27: =L25-L26 -> 3032.61
L28: 100
A29: Net Income (Loss) | H29: 67.12 | I29: =I12-I27 -> 212.014 | L29: =L27-L28 -> 2932.61

Sheet Logbook 04.24
A1: Logbook - Telfer BIPOC Business Society
A2: For the period of April 1 - April 30, 2024
A4: Logbook
A5: # | B5: Date | C5: Description | D5: Type | E5: Cheque # | F5: Deposit # | G5: Debit | H5: Credit | I5: Balance
I6: 2654.3
A7: 1 | B7: 45383 | C7: Monthly Bank Fee | D7: Bank Fee | G7: 6 | I7: =I6-G7+H7 -> 2648.3
A8: 2 | B8: 45397 | C8: E-Trans to Zyan: BBS Behind the Scenes Event | D8: Events | G8: 508.54 | I8: =I7-G8+H8 -> 2139.76
A9: 3 | B9: 45397 | C9: UOSU Funding: Winter 2024 | D9: Funding | H9: 314.24 | I9: =I8-G9+H9 -> 2454
A10: 4 | B10: 45404 | C10: E-Trans to Bhanuja: NFC Cards and Grad Sashes | D10: Other | G10: 583.99 | I10: =I9-G10+H10 -> 1870.01
A11: 5 | B11: 45411 | C11: E-Trans to Funmi: Club Website and Canva | D11: Other | G11: 73.9 | I11: =I10-G11+H11 -> 1796.11
A12: Amount Carried to Next Audit Period | I12: =I11 -> 1796.11
A14: Adjusted balance due to outstanding cheques | I14: =I12 -> 1796.11

Sheet Bank Rec 04.24
A1: Bank Reconciliation - Telfer BIPOC Business Society
A2: For the period of April 1 - April 30, 2024
E4: Debit | F4: Credit
A5: Bank statement balance on April 30, 2024 | F5: =1796.11 -> 1796.11
A6: Logbook balance on April 30, 2024 | F6: ='Logbook 04.24'!I12 -> 1796.11
A7: Difference | F7: 0
A9: Balance as per bank statement on April 30, 2024 | F9: =1796.11 -> 1796.11
A10: Add Deposits in Transit | F10: 0
A11: Subtract outstanding cheques
A12: Total outstanding cheques | F12: 0
A14: Balance as per logbook | F14: ='Logbook 04.24'!I14 -> 1796.11

Sheet  Logbook 05.24
A1: Logbook - Telfer BIPOC Business Society
A2: For the period of May 1 - June 3, 2024
A5: Logbook
A6: # | B6: Date | C6: Description | D6: Type | E6: Cheque # | F6: Deposit # | G6: Debit | H6: Credit | I6: Balance
I7: =1796.11 -> 1796.11
A8: 1 | B8: 45413 | C8: Monthly Bank Fee | D8: Bank Fee | G8: =6 -> 6 | I8: =I7-G8+H8 -> 1790.11
A9: Amount Carried to Next Audit Period | I9: =I8-H9 -> 1790.11
A11: Adjusted balance due to outstanding cheques | I11: =I9 -> 1790.11

Sheet  Bank Rec 05.24
A1: Bank Reconciliation - Telfer BIPOC Business Society
A2: For the period of May 1st - June 3, 2024
E4: Debit | F4: Credit
A5: Bank statement balance on June 3, 2024 | F5: =1790.11 -> 1790.11
A6: Logbook balance on June 3, 2024 | F6: =' Logbook 05.24'!I9 -> 1790.11
A7: Difference | F7: 0
A9: Balance as per bank statement on June 3, 2024 | F9: =1790.11 -> 1790.11
A10: Add Deposits in Transit | F10: 0
A11: Subtract outstanding cheques
A12: Total outstanding cheques | F12: 0
A14: Balance as per logbook | F14: =' Logbook 05.24'!I11 -> 1790.11

Sheet   Logbook 06.24
A1: Logbook - Telfer BIPOC Business Society
A2: For the period of June 3 - July 2, 2024
A5: Logbook
A6: # | B6: Date | C6: Description | D6: Type | E6: Cheque # | F6: Deposit # | G6: Debit | H6: Credit | I6: Balance
I7: =1790.11 -> 1790.11
A8: 1 | B8: 45446 | C8: Monthly Bank Fee | D8: Bank Fee | G8: =6 -> 6
A9: Amount Carried to Next Audit Period | I9: =I7-G8 -> 1784.11
A11: Adjusted balance due to outstanding cheques | I11: =I9 -> 1784.11

Sheet  Bank Rec 06.24
A1: Bank Reconciliation - Telfer BIPOC Business Society
A2: For the period of June 3 - July 2nd, 2024
E4: Debit | F4: Credit
A5: Bank statement balance on July 2nd, 2024 | F5: =1784.11 -> 1784.11
A6: Logbook balance on July 2nd, 2024 | F6: =' Logbook 06.24'!I9 -> 1784.11
A7: Difference | F7: 0
A9: Balance as per bank statement on July 2nd, 2024 | F9: =1784.11 -> 1784.11
A10: Add Deposits in Transit | F10: 0
A11: Subtract outstanding cheques
A12: Total outstanding cheques | F12: 0
A14: Balance as per logbook | F14: =' Logbook 06.24'!I11 -> 1784.11

Sheet  Logbook 07.24
A1: Logbook - Telfer BIPOC Business Society
A2: For the period of July 2nd - August 1st, 2024
A5: Logbook
A6: # | B6: Date | C6: Description | D6: Type | E6: Cheque # | F6: Deposit # | G6: Debit | H6: Credit | I6: Balance
I7: =' Bank Rec 06.24'!F14 -> 1784.11
A8: 1 | B8: 45475 | C8: Monthly Bank Fee | D8: Bank Fee | G8: =6 -> 6
A9: Amount Carried to Next Audit Period | I9: =I7-G8 -> 1778.11
A11: Adjusted balance due to outstanding cheques | I11: =I9 -> 1778.11

Sheet  Bank Rec 07.24
A1: Bank Reconciliation - Telfer BIPOC Business Society
A2: For the period of July 2nd- August 1st, 2024
E4: Debit | F4: Credit
A5: Bank statement balance on August 1st, 2024 | F5: =' Logbook 07.24'!I11 -> 1778.11
A6: Logbook balance on August 1st, 2024 | F6: =F5 -> 1778.11
A7: Difference | F7: 0
A9: Balance as per bank statement on August 1st, 2024 | F9: =F6 -> 1778.11
A10: Add Deposits in Transit | F10: 0
A11: Subtract outstanding cheques
A12: Total outstanding cheques | F12: =(F9+F10)-F11 -> 1778.11
A14: Balance as per logbook | F14: =F12 -> 1778.11

Sheet  Logbook 08.24
A1: Logbook - Telfer BIPOC Business Society
A2: For the period of August 1st, 2024- September 3rd, 2024
A5: Logbook
A6: # | B6: Date | C6: Description | D6: Type | E6: Cheque # | F6: Deposit # | G6: Debit | H6: Credit | I6: Balance
I7: =' Bank Rec 07.24'!F14 -> 1778.11
A8: 1 | B8: 45505 | C8: Monthly Bank Fee | D8: Bank Fee | G8: =6 -> 6 | I8: =I7-G8 -> 1772.11
A9: 2 | B9: 3-Sept-2024 | C9: E-Transfer to Alysse Hanisch | D9: Other | G9: 545.96 | I9: =I8-G9 -> 1226.15
A10: Amount Carried to Next Audit Period | I10: =I9 -> 1226.15
A12: Adjusted balance due to outstanding cheques | I12: =I10 -> 1226.15

Sheet  Bank Rec 08.24
A1: Bank Reconciliation - Telfer BIPOC Business Society
A2: For the period of August 1st, 2024- September 3rd, 2024
E4: Debit | F4: Credit
A5: Bank statement balance on September 3rd, 2024 | F5: =' Logbook 08.24'!I10 -> 1226.15
A6: Logbook balance on September 3rd, 2024 | F6: =F5 -> 1226.15
A7: Difference | F7: 0
A9: Balance as per bank statement on September 3rd, 2024 | F9: =F6 -> 1226.15
A10: Add Deposits in Transit | F10: 0
A11: Subtract outstanding cheques
A12: Total outstanding cheques | F12: =(F9+F10)-F11 -> 1226.15
A14: Balance as per logbook | F14: =F12 -> 1226.15

Sheet Logbook 09.24
A1: Logbook - Telfer BIPOC Business Society
A2: For the period of september3st, 2024-October 2nd
A5: Logbook
A6: # | B6: Date | C6: Description | D6: Type | E6: Cheque # | F6: Deposit # | G6: Debit | H6: Credit | I6: Balance
I7: =' Bank Rec 08.24'!F14 -> 1226.15
A8: 1 | B8: 45475 | C8: Monthly Bank Fee | D8: Bank Fee | G8: =6 -> 6
A9: Amount Carried to Next Audit Period | I9: =I7-G8 -> 1220.15
A11: Adjusted balance due to outstanding cheques | I11: =I9 -> 1220.15

Sheet  Bank Rec 09.24
A1: Bank Reconciliation - Telfer BIPOC Business Society
A2: For the period of september 3st, 2024-October 2nd
E4: Debit | F4: Credit
A5: Bank statement balance on August 1st, 2024 | F5: =' Logbook 07.24'!I11 -> 1778.11
A6: Logbook balance on August 1st, 2024 | F6: =F5 -> 1778.11
A7: Difference | F7: 0
A9: Balance as per bank statement on August 1st, 2024 | F9: =F6 -> 1778.11
A10: Add Deposits in Transit | F10: 0
A11: Subtract outstanding cheques
A12: Total outstanding cheques | F12: =(F9+F10)-F11 -> 1778.11
A14: Balance as per logbook | F14: =F12 -> 1778.11

Sheet Statement of Assets
A1: Statement of Assets - Telfer BIPOC Business Society
A2: 2024/2025
A4: Statement of Assets
A5: Asset | B5: Date of Purchase | C5: Purchase Price | D5: Depreciation Rate/Year | E5: Accumulated Depreciation/Year | F5: Accumulated Depreciation Value | G5: Current Value
A6: Name
A7: Name
A8: Name
A9: Name
A10: Name

Sheet Petty Cash Statement
A1: Petty Cash Statement - Telfer BIPOC Business Society
A2: 2024/2025
A4: Petty Cash Statement as of (date)
A5: Date | B5: Transaction | C5: Cash In | D5: Cash Out | E5: Balance
A6: Beginning Bal (date)
B7: Description
B8: Description
B9: Description
B10: Description
B11: Description
A12: Ending Bal (date)
